<robot
  name="selfass">
  <link
    name="base_link">
    <inertial>
      <origin
        xyz="-9.25383413112662E-19 0.0238066398638773 3.87702516807445E-06"
        rpy="0 0 0" />
      <mass
        value="0.265245594599213" />
      <inertia
        ixx="0"
        ixy="0"
        ixz="0"
        iyy="0"
        iyz="0"
        izz="0" />
    </inertial>
    <visual>
      <origin
        xyz="0 0 0"
        rpy="0 0 0" />
      <geometry>
        <mesh
          filename="package://selfass/meshes/base_link.STL" />
      </geometry>
      <material
        name="">
        <color
          rgba="1 1 1 0.3" />
      </material>
    </visual>
    <collision>
      <origin
        xyz="0 0 0"
        rpy="0 0 0" />
      <geometry>
        <mesh
          filename="package://selfass/meshes/base_link.STL" />
      </geometry>
    </collision>
  </link>
  <link
    name="lwheel">
    <inertial>
      <origin
        xyz="-4.9873E-17 1.3878E-17 -0.0125"
        rpy="0 0 0" />
      <mass
        value="0.070686" />
      <inertia
        ixx="0"
        ixy="0"
        ixz="0"
        iyy="0"
        iyz="0"
        izz="0" />
    </inertial>
    <visual>
      <origin
        xyz="0 0 0"
        rpy="0 0 0" />
      <geometry>
        <mesh
          filename="package://selfass/meshes/lwheel.STL" />
      </geometry>
      <material
        name="">
        <color
          rgba="1 1 1 1" />
      </material>
    </visual>
    <collision>
      <origin
        xyz="0 0 0"
        rpy="0 0 0" />
      <geometry>
        <mesh
          filename="package://selfass/meshes/lwheel.STL" />
      </geometry>
    </collision>
  </link>
  <joint
    name="j1"
    type="continuous">
    <origin
      xyz="0 0.0638 -0.032388"
      rpy="1.5708 -0.10184 6.2575E-18" />
    <parent
      link="base_link" />
    <child
      link="lwheel" />
    <axis
      xyz="0 0 1" />
    <dynamics
      damping="0.01"
      friction="0.5" />
  </joint>
  <link
    name="rwheel">
    <inertial>
      <origin
        xyz="2.949E-17 -1.0408E-17 -0.0125"
        rpy="0 0 0" />
      <mass
        value="0.070686" />
      <inertia
        ixx="0"
        ixy="0"
        ixz="0"
        iyy="0"
        iyz="0"
        izz="0" />
    </inertial>
    <visual>
      <origin
        xyz="0 0 0"
        rpy="0 0 0" />
      <geometry>
        <mesh
          filename="package://selfass/meshes/rwheel.STL" />
      </geometry>
      <material
        name="">
        <color
          rgba="1 1 1 1" />
      </material>
    </visual>
    <collision>
      <origin
        xyz="0 0 0"
        rpy="0 0 0" />
      <geometry>
        <mesh
          filename="package://selfass/meshes/rwheel.STL" />
      </geometry>
    </collision>
  </link>
  <joint
    name="jr2"
    type="continuous">
    <origin
      xyz="0 -0.0638 -0.032843"
      rpy="-1.5708 0.37529 -2.4122E-17" />
    <parent
      link="base_link" />
    <child
      link="rwheel" />
    <axis
      xyz="0 0 -1" />
    <dynamics
      damping="0.01"
      friction="0.5" />
  </joint>
</robot>